Workbook

Sheet 人員一覧・判定
A1: SIDEX-ACDR2026（シンガポール, 2026/10/27-30）ADRC派遣スタッフ一覧と判定
A2: 【v2_9 (2026/9/25)】9/25所内打合せ（Plaud）を反映: Day1のRT分割案（RT(1) 13:00-15:00、SC 15:15-16:15、RT(2) 29日09:00-09:30）、27日午前の大使表敬、3人目以降の費用方針、第6回合同会議を9/29午前へ、参加者登録状況（藤中 9/25）。Mizanのフライトのみ未確定。
A4: No. | B4: 氏名 | C4: Name | D4: 役職 | E4: 現地参加の確定度 | F4: 往路 | G4: 復路 | H4: 宿泊 | I4: デマケ上の担当（8/6版） | J4: 会期中の主な現地役割（本表での想定） | K4: 要確認・備考
A5: 1 | B5: 三浦 房紀 | C5: MIURA Fusanori | D5: センター長(Chairman) | E5: 確定 | F5: 10/26 SQ655 福岡09:30→SIN15:00 | G5: 10/31 SQ656 SIN01:20→福岡08:10 | H5: Dorsett 10/26-30 (5泊) | I5: ACDR2026 Opening 挨拶／SC出席 | J5: VIP対応（ADRC代表）。Opening (12:45)、Roundtable、SC、Gala、大使公邸レセプション、SIDEX Keynote出席 | K5: パスポート更新済み（7月）。復路は10/30深夜発扱い
A6: 2 | B6: 北本 政行 | C6: KITAMOTO Masayuki | D6: 常務理事 | E6: 確定 | F6: 10/26 SQ637 成田10:00→SIN16:30 | G6: 10/30 SQ638 SIN23:55→成田10/31 07:30 | H6: Dorsett 10/26-30 (5泊) | I6: （役員として出席） | J6: VIP対応。初参加のため事前ブリーフィング要。10/30は最終日夜に出発 | K6: 初参加。
A7: 3 | B7: 宮木 一寛 | C7: MIYAKI Kazuhiro | D7: 所長 | E7: 確定（フライト要確認） | F7: 10/25 NH2178 ITM 14:00 → NRT 15:30 NH803 NRT 17:00 → SIN 23:40 | G7: 10/31 NH802 SIN 06:35 → NRT 14:30 | H7: 10/25泊 必要（NH803 23:40着）→宿泊先（Dorsett/任意）を至急決定・手配。26日以降はDorsettシート「所長」行(10/26-30) | I7: 全体総括／内閣府との連絡調整／Bi-meeting／SC議長(内閣府)との調整／広報(記者クラブ) | J7: 全体総括。内閣府・COSEMとの調整に臨機応変に対応（内閣府には張り付かない。空港出迎え不要＝公用車。林統括官の英語対応はADRCには求められず大使館側）。Opening/VIP Tourに同行、SC進行補佐、Field Trip参加（9/4） | K7: 宿泊先（Dorsett/任意）は未定。10/26夜エリック長官夕食会（調整中）
A8: 4 | B8: 児玉 美樹 | C8: KODAMA Miki | D8: 研究部長 | E8: 確定（フライト要確認） | F8: 10/25 NH2178 ITM 14:00 → NRT 15:30 NH803 NRT 17:00 → SIN 23:40 | G8: 10/31 NH802 SIN 06:35 → NRT 14:30 NH2177 NRT 17:35 → ITM 19:00 | H8: Hotel Mi Bencoolen（Mシート: 10/26-30）→10/25泊の追加手配 必要（9/6確認） | I8: Bi-meeting／Welcome Reception(Program, MC)／レセプション手配／PC等機材サポート | J8: 現場統括。内閣府・COSEMとの調整に臨機応変に対応（ロジ専任にしない）。大使公邸レセプション（10/27）の設営・進行、10/29の事務局撤収（藤中と2名）、バイ会談調整（9/4） | K8: Hotel Miの10/25泊を追加手配。10/26夜エリック長官夕食会（調整中）。
A9: 5 | B9: 荒木田 勝 | C9: ARAKIDA Masaru | D9: リサーチフェロー | E9: 確定 | F9: 10/26 NH843 羽田00:25→SIN06:55 | G9: 10/30 NH844 SIN22:20→羽田10/31 05:55 | H9: Hotel Mi Bencoolen（Mシート: 10/26-30） | I9: 総括(PL)／Opening & Closing／SIDEX Conference／Field Trip／会場手配・機材／Zoom当日 | J9: 全体統括。Opening/Closing進行、会場・AV・Zoom/AI翻訳の当日運用、Field Trip引率、Google等リソース対応 | K9: 10/30 22:20発のためClosing後〜Day3午後まで在場。
A10: 6 | B10: 吉田 真紀 | C10: YOSHIDA Maki | D10: プロジェクト研究員（ジュネーブ） | E10: 確定 | F10: 10/25 AY1534 GVA 19:05 → HEL 23:10 AY131 HEL 00:05 → SIN 10/26 18:40 | G10: 10/30 AY132 SIN 22:05 → HEL 10/31 05:45 AY1531 HEL 07:55 → GVA 10:00 | H10: Hotel Mi Bencoolen（Mシート: 10/26-30） | I10: Roundtable(PIC)／Announcement／Web登録・コレポン／航空券(メンバー国)／Field Trip／Welcome Reception | J10: Roundtableセッション運営（ステートメント回収・共同モデレーター補佐）、レセプション進行補佐、Field Trip引率、参加者対応 | K10: フライト変更（吉田 9/6）: フィンエアー経由に変更、10/26 18:40着・10/30 22:05発。到着が夕方になるため10/26日中のDorsett到着対応には入れない。Hotel Mi 10/26-30泊はそのまま
A11: 7 | B11: 藤中 純子 | C11: FUJINAKA Junko | D11: 管理部 | E11: 確定 | F11: 10/25 TR819 関空11:30→SIN17:30 | G11: 11/1 TR818 SIN03:05→関空10:15 | H11: Hotel Mi Bencoolen 10/25-31 (7泊) | I11: レセプション手配／予算管理／契約・支払／宿泊・送迎の確認／SC議案・会計報告／SC事務（議案・進行・会計報告）（9/24 荒木田） | J11: 受付デスク（会場・レセプション）、ホテル・バス・支払の現地対応、SC事務、日当支払。SC事務（議案・進行・会計報告）を担当（森口不参加により 9/24） | K11: 先発隊。10/25着で前日準備
A12: 8 | B12: 田中 智美 | C12: TANAKA Tomomi | D12: 事務局(ACDR2026 Secretariat) | E12: 確定 | F12: 10/25 TR819 関空11:30→SIN17:30 | G12: 11/1 TR818 SIN03:05→関空10:15 | H12: Hotel Mi Bencoolen 10/25-31 (7泊) | I12: Announcement／Web登録確認・コレポン／航空券／VISA／宿泊・送迎(COSEM調整)／お礼状／日当 | J12: 受付デスク（会場・レセプション）、参加者リスト・名札(QR)管理、ホテル・送迎の現地コレポン、リソース対応 | K12: 先発隊。
A13: 9 | B13: 池田 誠 | C13: IKEDA Makoto | D13: 主任研究員 | E13: 確定（便名要確認） | F13: 10/26 SQ619 関空10:05→SIN16:00 | G13: 10/31 SQ622 SIN01:30→関空08:35 | H13: Hotel Mi Bencoolen（候補欄・未割当） | I13: Technical Session(PIC)／SIDEX Exhibition調整／会場手配・機材／PC等機材 | J13: Technical Session運営（登壇者対応・進行）、AV/PC操作（Day1）、SIDEX展示・Japan Pavilion連携
A14: 10 | B14: ジェラルド・エヘム・ポトゥタン | C14: Gerald Ejem Potutan | D14: 研究部次長 | E14: 確定（便名要確認） | F14: 10/26 SQ619 関空10:05→SIN16:00 | G14: 10/31 SQ622 SIN01:30→関空08:35 | H14: Hotel Mi Bencoolen（候補欄・未割当） | I14: 副総括／Concept Note／Roundtable／Draft Summary／広報／SCサマリーメモ | J14: Roundtable共同運営、Draft Summary執筆（Day1夜〜Day2朝）、SCメモ、必要に応じTechnical Session共同議長候補
A15: 11 | B15: ミザン ビスリ | C15: Mizan Bisri | D15: 研究員 | E15: 見込（手配未確認） | F15: 未確認 | G15: 未確認 | H15: Hotel Mi Bencoolen（候補欄・未割当） | I15: Technical Session(PIC)／SIDEX Exhibition調整／Draft Summary | J15: Technical Session ADRC側Co-Chair（有力案）。登壇者（JAXA・EOS-NTU・DOST・BRIN/ネパール代替・ウズベキスタン）との調整・当日進行 | K15: フライト未取得（9/4）
A16: 12 | B16: 藤本 絢子 | C16: FUJIMOTO Ayako | D16: 主任 | E16: 確定（本人承諾 9/4。スクート便を選択 9/24） | F16: 10/26 TR819 関西11:30→SIN17:30 | G16: 11/01 TR818 SIN03:05→関西10:15（チェックイン10/31夜。藤中・田中と同便） | H16: Hotel Mi Bencoolen 10/26-30（4泊、31日夜は空港へ）→手配状況要確認 | I16: アジェンダ(補)／広報・Flyer／Zoom webinar設定／Webサイト／各種リスト出力(リソース・研究部)／会議参加証明 | J16: 撮影（写真・動画）を主担当（児玉 9/4）。加えて公邸レセプションの設営補助、Zoom/AI翻訳の現地一次対応、参加者誘導
A17: 13 | B17: 塩見 有美 | C17: SHIOMI Yumi | D17: 主任研究員 | E17: 確定（本人承諾 9/4。TG便を9/9にケイラインへ発注依頼） | F17: 10/26 TG623 関西11:00→バンコク15:30／TG409 バンコク16:35→SIN19:55 | G17: 10/30 TG410 SIN21:00→バンコク22:20／TG622 バンコク23:59→関西10/31 07:20 | H17: Hotel Mi Bencoolen 10/26-30（4泊）→要手配。Miに空きがなければ周辺ホテルを追加手配（荒木田 9/7） | I17: （デマケ上の現地担当なし） | J17: セッション記録・サマリー補助（2023年はS1サマリー担当）、中央アジア/ウズベキスタン対応、参加者誘導 | K17: 30日は閉会16:50後すぐ空港へ移動。Hotel Miの手配状況を要確認
A18: 15 | B18: 中村 | C18: NAKAMURA | D18: （研究部） | E18: 国内サポート（確定） | F18: ― | G18: ― | H18: ―（神戸） | I18: （デマケ8/6版に記載なし→追記要） | J18: 【日本側】Zoom Webinar/Meetingの設定・ホスト、AI通訳ツールの設定と会期中の監視、オンラインQ&A・コメント欄の確認。会期前にリハーサル（2025年と同じ体制。ACDR2025動態表: Setup Webinar・Webinar Rehearsal・Check Q&A） | K18: 時差: 神戸はシンガポールより1時間進む（SGT 09:30 = JST 10:30）
A19: 16 | B19: 山口 | C19: YAMAGUCHI | D19: （研究部） | E19: 国内サポート（確定） | F19: ― | G19: ― | H19: ―（神戸） | I19: （デマケ8/6版に記載なし→追記要） | J19: 【日本側】ACDRセッションの録画（Webinar/Zoomクラウド録画＋ローカル保存）、オンライン参加者の質疑対応（Q&A取次・チャット回答）、録画データの整理・保存 | K19: オンライン質疑は中村（Q&A確認）と分担
A20: 17 | B20: 伊達 孝 | C20: DATE Takashi | D20: ― | E20: 国内サポート | F20: ― | G20: ― | H20: ― | I20: PC等機材サポート／Webサイトサポート | J20: 神戸からのリモート支援（Web更新、Highlights発行） | K20: 2025年はWebinar設定・ホスト/録画確認を担当。
A21: 18 | B21: 寺坂 佳津子 | C21: TERASAKA Kazuko | D21: アシスタント | E21: 国内（オンライン登録） | F21: ― | G21: ― | H21: ― | I21: 参加者情報・フライト・宿泊・送迎のWeb登録・リスト出力(メンバー国)／VISA | J21: 神戸でマスターリスト管理・リスト出力 | K21: 2025年は録画（日英2台）・ローカル保存を担当。
A22: 19 | B22: 田原 麻衣 | C22: TAHARA Mai | D22: 管理部 | E22: 国内（オンライン登録） | F22: ― | G22: ― | H22: ― | I22: 管理部（役員対応） | J22: 神戸で管理部業務 | K22: ―
A23: 20 | B23: 立部 知保里 | C23: TATEBE Chihori | D23: 研究員 | E23: 国内（オンライン登録） | F23: ― | G23: ― | H23: ― | J23: 神戸 | K23: トルコ研修調整で多忙（児玉 5/18）
B25: 集計（自動計算）
B26: 現地参加 確定（フライト要確認含む） | E26: =COUNTIF(E5:E23,"確定*")
B27: 見込・候補（手配未了） | E27: =COUNTIF(E5:E23,"見込*")+COUNTIF(E5:E23,"候補*")
B28: 未定 | E28: =COUNTIF(E5:E23,"未定*")
B29: うち役員（三浦・北本・宮木）＝運営要員から除く | E29: 3
B30: 実働運営要員（確定＋見込(Mizan)−役員） | E30: =E26+COUNTIF(E5:E23,"見込*")-E29 | F30: ← ACDR2023（ドゥシャンベ）の現地運営要員は役員（小川・笹原）を除き8名（堀池・藤中・田中・荒木田・児玉・塩見・Potutan・吉田）。今回は同数だが、公邸レセプション・Gala・Parade・SIDEX連携が加わる
B31: 日本側サポート（中村・山口 確定、寺坂・伊達 仮置き） | E31: =COUNTIF(E5:E23,"国内サポート（確定）")
B32: 凡例
C33: 確定（航空券発券済み／確定情報あり）
C34: 見込・候補（本人可または担当割当済みだが手配未了）
C35: 未定（打診中・根拠不足）
C36: 国内・オンライン参加

Sheet 動態表(日別)
A1: ACDR2026 動態表（日別 AM/PM） as of 25 Sep 2026 v2_9（9/25 所内打合せ反映）
G2: 10/26夜: エリック長官夕食会（宮木・三浦・児玉。北本理事は辞退〈10/2 児玉→Sylvia〉）
A3: Staff | B3: 10/24(土) | D3: 10/25(日) | F3: 10/26(月) | H3: 10/27(火) | J3: 10/28(水) | L3: 10/29(木) | N3: 10/30(金) | P3: 10/31(土) | R3: 11/1(日)
B4: AM | C4: PM | D4: AM | E4: PM | F4: AM | G4: PM | H4: AM | I4: PM | J4: AM | K4: PM | L4: AM | M4: PM | N4: AM | O4: PM | P4: AM | Q4: PM | R4: AM | S4: PM
A5: PROGRAM | F5: 参加者到着(Dorsett) | G5: 参加者到着(〜深夜)／Day-1準備 | H5: 参加者到着／会場・名札準備／役員は会場を短時間下見後に大使館表敬（午前・足立氏と調整） | I5: 16:00設営→19:00-21:00 大使公邸レセプション | J5: 07:30会場テスト／10:00 Joint Opening／VIP Tour | K5: 12:45 ACDR Opening／13:00-15:00 Roundtable(1)／15:15-16:15 SC／17:30 Dorsett発／18:30 Gala ※RT分割・SC前倒しは9/25所内案、COSEM・内閣府と調整中 | L5: 09:00-09:30 Roundtable(2)（案）／09:30 Technical Session／11:30 Summary & Closing | M5: 13:00〜 Field Trip(CDA)／18:30 SCDF Parade & Dinner | N5: 09:00 SIDEX Keynote/Panel1 | O5: 13:50 Exhibition Tour／15:00 Panel2／16:30閉会／夜:出発 | P5: 参加者出発(見送り) | Q5: 参加者出発
A6: =人員一覧・判定!B5 | F6: FUK-SIN(SQ655) | G6: SIN着15:00/Dorsett/夜:エリック長官夕食会(調整中) | H6: 会場下見(全員)/資料確認 | I6: レセプション(VIP) | J6: Joint Opening/VIP Tour | K6: ACDR Opening挨拶/RT/SC/Gala | L6: Tech Session/Closing | M6: Field Trip/Parade Dinner | N6: SIDEX Keynote | O6: Panel2/閉会 | P6: SIN-FUK(SQ656 01:20)
A7: =人員一覧・判定!B6 | F7: NRT-SIN(SQ637) | G7: SIN着16:30/Dorsett/夜:エリック長官夕食会(調整中) | H7: 会場下見(全員)→ブリーフィング(荒木田) | I7: レセプション(VIP) | J7: Joint Opening/VIP Tour | K7: RT/SC/Gala | L7: Tech Session/Closing | M7: Field Trip/Parade Dinner | N7: SIDEX Keynote | O7: Panel2/閉会/SIN-NRT(SQ638 23:55) | P7: NRT着07:30
A8: =人員一覧・判定!B7 | E8: ITM-NRT-SIN(NH2178/NH803) 23:40着 | F8: 内閣府到着対応準備/COSEM調整 | G8: 内閣府到着確認(出迎え不要・公用車)/COSEM調整/夜:エリック長官夕食会(調整中) | H8: 会場下見(全員)→COSEM・内閣府調整 | I8: レセプション(内閣府随行・大使対応) | J8: 事務局・受付設営/Opening/VIP Tour(内閣府に同行) | K8: ACDR Opening/RT/SC進行補佐/Gala | L8: Tech Session/Closing | M8: Field Trip/Parade Dinner | N8: SIDEX Keynote(内閣府随行) | O8: Panel2/閉会 | P8: SIN-NRT(NH802 06:35)
A9: =人員一覧・判定!B8 | E9: ITM-NRT-SIN(NH2178/NH803) 23:40着 | F9: Dorsett受付準備/COSEM打合せ | G9: Dorsettフロント対応(到着ピーク)/接続テスト①/夜:エリック長官夕食会(調整中) | H9: 会場下見(全員)→公邸・ケータリング最終確認 | I9: 16:00公邸設営/MC・進行 | J9: 07:30会場テスト/事務局設営/Opening/COSEM調整 | K9: RT/SC/Gala引率 | L9: Tech Session/Closing | M9: 事務局撤収(藤中と)/Parade Dinner | N9: SIDEX Keynote | O9: Exhibition Tour/Panel2/閉会 | P9: SIN-NRT-ITM(NH802 06:35)
A10: =人員一覧・判定!B9 | F10: SIN着06:55(NH843)/会場・機材確認 | G10: Dorsettフロント対応/内閣府到着対応/日本側(中村・山口)とZoom・AI通訳接続テスト①(JST 15-17) | H10: 会場下見引率(全員)→北本ブリーフ/持込PCで接続テスト② | I10: 日本側と接続テスト②(Webinar・AI通訳・録画, JST 14-17)→公邸設営/レセプション運営 | J10: 07:30会場・NWテスト/Zoom/Opening進行 | K10: ACDR Opening進行/RT運営(AV)/SC/Gala | L10: Tech Session(AV・Zoom)/Summary/Closing進行 | M10: Field Trip引率 | N10: SIDEX Keynote(リソース対応) | O10: Exhibition Tour/Panel2/閉会/SIN-HND(NH844 22:20) | P10: HND着05:55
A11: =人員一覧・判定!B10 | D11: GVA-HEL(AY1534 19:05発) | E11: HEL-SIN(AY131 00:05発) | F11: フライト移動中(AY131) | G11: SIN着18:40→Hotel Mi/夜:参加者対応 | H11: 会場下見(全員)→公邸・ケータリング最終確認 | I11: 16:00公邸設営/受付/進行補佐 | J11: Opening/参加者誘導 | K11: RT運営(PIC)/SC/Gala引率 | L11: Tech Session(記録) | M11: Field Trip引率/ホテル→EXPO誘導(パレード)/Parade Dinner | N11: Dorsett→EXPO誘導/SIDEX Keynote | O11: Panel2/閉会/SIN-HEL(AY132 22:05) | P11: HEL経由 GVA着10:00
A12: =人員一覧・判定!B11 | D12: KIX-SIN(TR819) | E12: SIN着17:30/Hotel Mi | F12: COSEM打合せ/Dorsett受付準備 | G12: Dorsettフロント対応(到着ピーク) | H12: Dorsett受付(下見は交代で)/名札セット | I12: 公邸受付/名札配布 | J12: 受付デスク(Peridot) | K12: 受付/SC事務(議案・進行・会計報告)/Gala | L12: 受付デスク/支払 | M12: 事務局撤収(児玉と)/精算/Parade Dinner | N12: SIDEX(受付・清算) | O12: 出発案内/支払 | P12: 見送り/清算 | Q12: SIN-KIX(TR818 11/1 03:05) | R12: SIN-KIX(TR818 03:05) | S12: KIX着10:15
A13: =人員一覧・判定!B12 | D13: KIX-SIN(TR819) | E13: SIN着17:30/Hotel Mi | F13: 名札(QR)受取/リスト確認 | G13: Dorsettフロント対応(到着ピーク) | H13: Dorsett受付(下見は交代で)/送迎確認 | I13: 公邸受付/名札配布 | J13: 受付デスク(Peridot) | K13: 受付/RT/Gala引率 | L13: Dorsett→EXPO誘導/受付デスク | M13: Field Trip名簿/ホテル→EXPO誘導(パレード)/Parade Dinner | N13: Dorsett→EXPO誘導/SIDEX(受付) | O13: 出発案内(送迎) | P13: 見送り | Q13: SIN-KIX(TR818 11/1 03:05) | R13: SIN-KIX(TR818 03:05) | S13: KIX着10:15
A14: =人員一覧・判定!B13 | F14: KIX-SIN(SQ619) | G14: SIN着16:00/Hotel Mi/日本側と接続テスト①に合流 | H14: 会場下見(全員)→Japan Pavilion確認/接続テスト② | I14: 16:00公邸設営補助/レセプション | J14: 07:30会場テスト/AV・PC操作 | K14: RT(AV・PC)/Gala | L14: Tech Session運営(PIC) | M14: Field Trip or SIDEX展示調整/Parade Dinner | N14: SIDEX Keynote | O14: Exhibition Tour(誘導)/Panel2 | P14: SIN-KIX(01:30発 便名要確認)
A15: =人員一覧・判定!C14 | F15: KIX-SIN(SQ619) | G15: SIN着16:00/Hotel Mi | H15: 会場下見(全員)→RT準備 | I15: 16:00公邸設営補助/レセプション | J15: Opening | K15: RT運営(共同)/ノート/SCメモ/Gala | L15: Tech Session(ノート)/Draft Summary | M15: Field Trip/Parade Dinner | N15: SIDEX Keynote/Summary | O15: Panel2/閉会 | P15: SIN-KIX(01:30発 便名要確認)
A16: =人員一覧・判定!C15 | F16: (未手配) | G16: (未手配) | H16: 会場下見(全員)→登壇者対応 | I16: 16:00公邸設営補助/レセプション | J16: Opening | K16: RT(ノート)/Gala | L16: Tech Session Co-Chair | M16: Field Trip/Parade Dinner | N16: SIDEX Keynote | O16: Panel2/閉会 | P16: (未手配)
A17: =人員一覧・判定!B16 | F17: KIX-SIN(TR819) | G17: SIN着17:30→Hotel Mi | H17: 会場下見(全員)→公邸・ケータリング最終確認/撮影準備 | I17: 16:00公邸設営・MC進行確認/撮影 | J17: Zoom・AI翻訳/写真 | K17: 受付/Zoom/写真/Gala | L17: Zoom・AI翻訳/写真 | M17: Japan Pavilion/参加者誘導 | N17: SIDEX(写真・誘導) | O17: Exhibition Tour誘導/閉会/深夜:空港へ（藤中・田中と同行） | P17: SIN-KIX(TR818 03:05発) KIX着10:15
A18: =人員一覧・判定!B17 | F18: KIX-BKK-SIN(TG623/TG409) | G18: SIN着19:55→Hotel Mi | H18: 会場下見(全員)→到着者対応 | I18: 16:00公邸設営補助/レセプション | J18: Opening/参加者誘導 | K18: RT記録・サマリー補助/Gala | L18: Dorsett→EXPO誘導/Tech Session記録 | M18: Field Trip/ホテル→EXPO誘導(パレード)/Parade Dinner | N18: SIDEX Keynote/サマリー | O18: Panel2/閉会/空港へ(TG410 21:00発) | P18: BKK経由 KIX着07:20
A19: 在場人数(役員・藤本・塩見含む) | B19: =COUNTA(B6:B18)-COUNTIF(B6:B18,"*未手配*")-COUNTIF(B6:B18,"*要確認*")-COUNTIF(B6:B18,"*NRT着*")-COUNTIF(B6:B18,"*HND着*")-COUNTIF(B6:B18,"*KIX着*")-COUNTIF(B6:B18,"*GVA着*") | C19: =COUNTA(C6:C18)-COUNTIF(C6:C18,"*未手配*")-COUNTIF(C6:C18,"*要確認*")-COUNTIF(C6:C18,"*NRT着*")-COUNTIF(C6:C18,"*HND着*")-COUNTIF(C6:C18,"*KIX着*")-COUNTIF(C6:C18,"*GVA着*") | D19: =COUNTA(D6:D18)-COUNTIF(D6:D18,"*未手配*")-COUNTIF(D6:D18,"*要確認*")-COUNTIF(D6:D18,"*NRT着*")-COUNTIF(D6:D18,"*HND着*")-COUNTIF(D6:D18,"*KIX着*")-COUNTIF(D6:D18,"*GVA着*") | E19: =COUNTA(E6:E18)-COUNTIF(E6:E18,"*未手配*")-COUNTIF(E6:E18,"*要確認*")-COUNTIF(E6:E18,"*NRT着*")-COUNTIF(E6:E18,"*HND着*")-COUNTIF(E6:E18,"*KIX着*")-COUNTIF(E6:E18,"*GVA着*") | F19: =COUNTA(F6:F18)-COUNTIF(F6:F18,"*未手配*")-COUNTIF(F6:F18,"*要確認*")-COUNTIF(F6:F18,"*NRT着*")-COUNTIF(F6:F18,"*HND着*")-COUNTIF(F6:F18,"*KIX着*")-COUNTIF(F6:F18,"*GVA着*") | G19: =COUNTA(G6:G18)-COUNTIF(G6:G18,"*未手配*")-COUNTIF(G6:G18,"*要確認*")-COUNTIF(G6:G18,"*NRT着*")-COUNTIF(G6:G18,"*HND着*")-COUNTIF(G6:G18,"*KIX着*")-COUNTIF(G6:G18,"*GVA着*") | H19: =COUNTA(H6:H18)-COUNTIF(H6:H18,"*未手配*")-COUNTIF(H6:H18,"*要確認*")-COUNTIF(H6:H18,"*NRT着*")-COUNTIF(H6:H18,"*HND着*")-COUNTIF(H6:H18,"*KIX着*")-COUNTIF(H6:H18,"*GVA着*") | I19: =COUNTA(I6:I18)-COUNTIF(I6:I18,"*未手配*")-COUNTIF(I6:I18,"*要確認*")-COUNTIF(I6:I18,"*NRT着*")-COUNTIF(I6:I18,"*HND着*")-COUNTIF(I6:I18,"*KIX着*")-COUNTIF(I6:I18,"*GVA着*") | ... S19: =COUNTA(S6:S18)-COUNTIF(S6:S18,"*未手配*")-COUNTIF(S6:S18,"*要確認*")-COUNTIF(S6:S18,"*NRT着*")-COUNTIF(S6:S18,"*HND着*")-COUNTIF(S6:S18,"*KIX着*")-COUNTIF(S6:S18,"*GVA着*")
A20: うち藤本・塩見 | B20: =COUNTA(B17:B18)-COUNTIF(B17:B18,"*未手配*")-COUNTIF(B17:B18,"*要確認*")-COUNTIF(B17:B18,"*NRT着*")-COUNTIF(B17:B18,"*HND着*")-COUNTIF(B17:B18,"*KIX着*")-COUNTIF(B17:B18,"*GVA着*") | C20: =COUNTA(C17:C18)-COUNTIF(C17:C18,"*未手配*")-COUNTIF(C17:C18,"*要確認*")-COUNTIF(C17:C18,"*NRT着*")-COUNTIF(C17:C18,"*HND着*")-COUNTIF(C17:C18,"*KIX着*")-COUNTIF(C17:C18,"*GVA着*") | D20: =COUNTA(D17:D18)-COUNTIF(D17:D18,"*未手配*")-COUNTIF(D17:D18,"*要確認*")-COUNTIF(D17:D18,"*NRT着*")-COUNTIF(D17:D18,"*HND着*")-COUNTIF(D17:D18,"*KIX着*")-COUNTIF(D17:D18,"*GVA着*") | E20: =COUNTA(E17:E18)-COUNTIF(E17:E18,"*未手配*")-COUNTIF(E17:E18,"*要確認*")-COUNTIF(E17:E18,"*NRT着*")-COUNTIF(E17:E18,"*HND着*")-COUNTIF(E17:E18,"*KIX着*")-COUNTIF(E17:E18,"*GVA着*") | F20: =COUNTA(F17:F18)-COUNTIF(F17:F18,"*未手配*")-COUNTIF(F17:F18,"*要確認*")-COUNTIF(F17:F18,"*NRT着*")-COUNTIF(F17:F18,"*HND着*")-COUNTIF(F17:F18,"*KIX着*")-COUNTIF(F17:F18,"*GVA着*") | G20: =COUNTA(G17:G18)-COUNTIF(G17:G18,"*未手配*")-COUNTIF(G17:G18,"*要確認*")-COUNTIF(G17:G18,"*NRT着*")-COUNTIF(G17:G18,"*HND着*")-COUNTIF(G17:G18,"*KIX着*")-COUNTIF(G17:G18,"*GVA着*") | H20: =COUNTA(H17:H18)-COUNTIF(H17:H18,"*未手配*")-COUNTIF(H17:H18,"*要確認*")-COUNTIF(H17:H18,"*NRT着*")-COUNTIF(H17:H18,"*HND着*")-COUNTIF(H17:H18,"*KIX着*")-COUNTIF(H17:H18,"*GVA着*") | I20: =COUNTA(I17:I18)-COUNTIF(I17:I18,"*未手配*")-COUNTIF(I17:I18,"*要確認*")-COUNTIF(I17:I18,"*NRT着*")-COUNTIF(I17:I18,"*HND着*")-COUNTIF(I17:I18,"*KIX着*")-COUNTIF(I17:I18,"*GVA着*") | ... S20: =COUNTA(S17:S18)-COUNTIF(S17:S18,"*未手配*")-COUNTIF(S17:S18,"*要確認*")-COUNTIF(S17:S18,"*NRT着*")-COUNTIF(S17:S18,"*HND着*")-COUNTIF(S17:S18,"*KIX着*")-COUNTIF(S17:S18,"*GVA着*")
A21: ※自動計算は『記入があり、かつ未手配・要確認・日本側到着(NRT着/HND着/KIX着/GVA着)を除く』人数で、フライト移動中を含む。藤本・塩見は本人承諾済み（塩見はTG便を発注依頼済み、藤本は便名未確認）。手配前の日は「未手配」表記で件数から外れる。
A22: None
A23: 日本側サポート（神戸） ※JST = SGT + 1時間
A24: =人員一覧・判定!B18 | F24: Webinar/Zoom/AI通訳 設定・リハーサル | G24: 現地(荒木田・池田)と接続テスト①(JST 15-17) | H24: AI通訳ツール最終設定 | I24: Webinar・Zoomホスト設定/接続テスト②(JST 14-17)/SCリハ(Q&A確認) | J24: Webinar開始/AI通訳監視 (JST 9:30-) | K24: RT・SC: Q&A/コメント確認・AI通訳監視 | L24: TS: Q&A/コメント確認・AI通訳監視 | M24: （配信なし）ログ回収 | N24: （SIDEX配信はSCDF側） | O24: Webinar/Zoom終了処理
A25: =人員一覧・判定!B19 | F25: 録画設定テスト(クラウド+ローカル) | H25: 録画リハーサル | I25: 接続テスト②(録画・Q&A確認)/SCリハ録画 | J25: Opening/RT 録画・オンライン質疑 | K25: SC 録画 | L25: TS/Closing 録画・オンライン質疑 | M25: 録画データ整理・保存 | O25: 録画データ整理・保存
A26: =人員一覧・判定!B21 | H26: 録画テスト(日英2台) ※仮置き | J26: 録画(日英)ローカル保存 ※仮置き | K26: 録画(日英)ローカル保存 ※仮置き | L26: 録画(日英)ローカル保存 ※仮置き
A27: =人員一覧・判定!B20 | H27: Webinar設定・ホスト/録画確認 ※仮置き | J27: Webinarホスト・録画確認 ※仮置き | K27: SC Zoom設定 ※仮置き | L27: Webinarホスト・録画確認 ※仮置き

Sheet 27Oct(Day0)
A1: 27 OCT 2026 (TUE) Day 0: 参加者到着・大使公邸レセプション（SJ60 Commemorative Reception） ※27日午前: 全員で会場下見・ホテル動線確認（会場は27日午後以降しか使えないため設営不可、持込PCでの接続テストのみ）
B3: 7:00 | D3: 8:00 | F3: 9:00 | H3: 10:00 | J3: 11:00 | L3: 12:00 | N3: 13:00 | P3: 14:00 | R3: 15:00 | T3: 16:00 | V3: 17:00 | X3: 18:00 | Z3: 19:00 | AB3: 20:00 | AD3: 21:00 | AF3: 22:00
A4: PROGRAM | B4: 参加者到着(Dorsett): 07:15モルディブ/08:10スリランカ/08:45アルメニア・トルコ・ウズベキスタン/11:15パキスタン/11:20インドネシア | L4: 到着: 12:20マレーシア/14:30ブルネイ/14:50タイ/15:10ミャンマー | T4: 大使公邸 設営（名札セット持込・受付配置） | Z4: レセプション 19:00-21:00（大使挨拶・乾杯・内閣府発表） | AE4: 撤収
A6: =人員一覧・判定!B5 | H6: 会場を短時間下見→大使館表敬（午前、足立氏と時間調整。26日は長官夕食会のため不可） | Y6: レセプション出席(VIP)
A7: =人員一覧・判定!B6 | H7: 会場を短時間下見→大使館表敬（午前、足立氏と時間調整。26日は長官夕食会のため不可） | Y7: レセプション出席(VIP)
A8: =人員一覧・判定!B7 | F8: 会場を短時間下見→大使館表敬（午前、足立氏と時間調整。26日は長官夕食会のため不可） | W8: レセプション(大使・内閣府対応)
A9: =人員一覧・判定!B8 | F9: 会場下見(全員 9-11)→公邸・ケータリング最終確認 | T9: 公邸設営・MC進行確認 | Y9: MC/進行
A10: =人員一覧・判定!B9 | F10: 会場下見引率(全員 9-11) | H10: →北本ブリーフ(11:00-) | N10: 機材・Zoom・AI通訳準備／日本側(中村・山口)と接続テスト②(JST14-17) | T10: 公邸設営・運営・撤収
A11: =人員一覧・判定!B10 | F11: 会場下見(全員 9-11)→公邸・ケータリング最終確認 | T11: 公邸受付準備 | Y11: 受付/進行補佐
A12: =人員一覧・判定!B11 | D12: Dorsett受付(到着者対応)／下見は交代で | T12: 公邸受付準備(名札セット) | Y12: 受付/名札配布
A13: =人員一覧・判定!B12 | D13: Dorsett受付(到着者・送迎確認)／下見は交代で | T13: 公邸受付準備 | Y13: 受付/名札配布
A14: =人員一覧・判定!B13 | F14: 会場下見(全員 9-11)→Japan Pavilion確認 | N14: 機材準備／日本側と接続テスト②(録画・Q&A確認) | W14: レセプション(設営補助)
A15: =人員一覧・判定!C14 | F15: 会場下見(全員 9-11)→RT/Summary準備 | N15: 到着者対応補助 | T15: 公邸設営補助 | W15: レセプション
A16: =人員一覧・判定!C15 | F16: 会場下見(全員 9-11)→登壇者連絡・接続テスト | N16: 到着者対応補助 | T16: 公邸設営補助 | W16: レセプション
A17: =人員一覧・判定!B16 | F17: 会場下見(全員 9-11)→公邸・ケータリング最終確認/撮影準備 | N17: 到着者対応補助 | T17: 公邸設営・MC進行確認 | Y17: 写真
A18: =人員一覧・判定!B17 | F18: 会場下見(全員 9-11)→到着者対応(ウズベキスタン等) | T18: 公邸設営補助 | W18: レセプション受付補助
A19: 稼働人数(自動) | B19: =COUNTA(B5:B18) | C19: =COUNTA(C5:C18) | D19: =COUNTA(D5:D18) | E19: =COUNTA(E5:E18) | F19: =COUNTA(F5:F18) | G19: =COUNTA(G5:G18) | H19: =COUNTA(H5:H18) | I19: =COUNTA(I5:I18) | ... AG19: =COUNTA(AG5:AG18)
A21: 留意事項: (1) 19:00-21:00に受付(名札セット配布100-120名)・MC・VIP対応・写真・バス誘導(Dorsett→公邸)が同時発生。受付2名(藤中・田中)＋吉田で名札配布、藤本が写真。 (2) 27日午前は全員で会場下見のため、Dorsettは藤中・田中のみ。午後はDorsett到着対応と公邸設営準備が並行、荒木田・池田は機材、児玉と吉田は公邸に張り付く。それ以外は到着対応補助。 (3) 開始が19:00（8/26版アジェンダ）に後ろ倒しになったため、Dorsett→公邸の送迎バス出発（従来想定17:30〜18:30）と撤収時刻をCOSEMと再確認する必要がある。 (4)【9/25】役員（三浦・北本・宮木）は27日午前に会場を短時間見た後、大使館へ表敬（荒木田が足立氏と調整）。会場の前日設営が可能な時刻が判明したら、公邸レセプションを外れて設営に残る者を決める。
A23: 日本側サポート（神戸）※列はシンガポール時間、JSTは+1時間
A24: =人員一覧・判定!B18 | F24: AI通訳ツール最終設定 (JST10-13) | N24: 接続テスト②: Webinar/Zoomホスト設定・現地(荒木田・池田)と接続 (JST14-17)
A25: =人員一覧・判定!B19 | F25: 録画設定テスト(クラウド+ローカル) | N25: 接続テスト②参加・録画リハ
A26: =人員一覧・判定!B21 | N26: 録画テスト(日英2台)
A27: =人員一覧・判定!B20 | N27: Webinar設定・ホスト/録画確認

Sheet 28Oct(Day1)
A1: 28 OCT 2026 (WED) Day 1: Joint Opening / ACDR Opening / Roundtable / SC / Gala Dinner
B3: 7:00 | D3: 8:00 | F3: 9:00 | H3: 10:00 | J3: 11:00 | L3: 12:00 | N3: 13:00 | P3: 14:00 | R3: 15:00 | T3: 16:00 | V3: 17:00 | X3: 18:00 | Z3: 19:00 | AB3: 20:00 | AD3: 21:00 | AF3: 22:00
A4: PROGRAM | C4: 会場・NW最終テスト(演台・客席・事務局部屋)／事務局部屋立上げ／Hotel Mi→EXPO バス | H4: Joint Opening (Hall 3) | I4: VIP Tour／Japan Pavilion（開会式ではなくVIPツアー立寄り時の展示挨拶）／11:15表敬 ※ADRC参加者のEXPO見学はVIPツアーに合わせ短縮 | K4: Lunch (Hall 3) | M4: ACDR Opening | N4: Roundtable (1) (Peridot) 13:00-15:00 ※9/25案: 30分短縮し続きを29日09:00に。SCDFモデレーター+メンバー国Co-Mod | S4: Steering Committee 15:15-16:15（9/25案: 30分前倒し） | W4: Dorsett 17:30発→Orchard Hotel | Y4: SIDEX Gala Dinner (Grand Ballroom)
A6: =人員一覧・判定!B5 | G6: Joint Opening/VIP Tour | M6: ACDR Opening 挨拶 | N6: Roundtable | S6: SC | W6: Gala
A7: =人員一覧・判定!B6 | G7: Joint Opening/VIP Tour | M7: Opening/Roundtable | S7: SC | W7: Gala
A8: =人員一覧・判定!B7 | F8: Opening/VIP Tour(内閣府に同行、随行ではない) | M8: Opening/RT(内閣府随行) | S8: SC(議長=内閣府 補佐) | W8: Gala(内閣府随行)
A9: =人員一覧・判定!B8 | C9: 会場テスト/事務局部屋 | G9: COSEM調整・VIP動線(臨機応変) | M9: RT(バイ会談調整) | S9: SC | V9: Gala引率(バス)
A10: =人員一覧・判定!B9 | C10: 会場・NW・Zoom・AI通訳テスト／日本側と接続確認 | G10: Opening進行確認/VIP Tour同行 | M10: ACDR Opening進行 | N10: RT AV/Zoom運用 | S10: SC(記録) | W10: Gala
A11: =人員一覧・判定!B10 | D11: RT準備(ステートメント・席札) | G11: 参加者誘導 | M11: RT運営(PIC) | S11: SC補助 | V11: Gala引率
A12: =人員一覧・判定!B11 | C12: Dorsett送り出し担当 | G12: 受付デスク設営・運営(Peridot) | M12: 受付/RT | S12: SC事務(議案・進行・会計報告) | W12: Gala
A13: =人員一覧・判定!B12 | C13: Dorsett送り出し担当 | G13: 受付デスク設営・運営(Peridot) | M13: 受付/RT | S13: 受付 | V13: Gala引率(名簿)
A14: =人員一覧・判定!B13 | C14: 会場AVテスト／日本側と接続確認 | G14: Japan Pavilion連携 | M14: RT PC・スクリーン操作 | S14: SC(AV) | W14: Gala
A15: =人員一覧・判定!C14 | C15: 事務局部屋・受付デスク設営 | G15: Opening | M15: RT共同運営/ノート | S15: SCメモ | W15: Gala | AD15: Draft Summary執筆
A16: =人員一覧・判定!C15 | C16: Hotel Me送り出し担当 | G16: Opening | M16: RTノート/翌日登壇者対応 | S16: 登壇者リハ調整 | W16: Gala
A17: =人員一覧・判定!B16 | C17: Zoom/AI翻訳セットアップ | G17: 写真/誘導 | M17: Zoom・AI翻訳オペ/写真 | W17: Gala(写真)
A18: =人員一覧・判定!B17 | C18: Hotel Me送り出し担当 | G18: 参加者誘導 | M18: RT記録 | S18: SC記録補助 | W18: Gala
A19: 稼働人数(自動) | B19: =COUNTA(B5:B18) | C19: =COUNTA(C5:C18) | D19: =COUNTA(D5:D18) | E19: =COUNTA(E5:E18) | F19: =COUNTA(F5:F18) | G19: =COUNTA(G5:G18) | H19: =COUNTA(H5:H18) | I19: =COUNTA(I5:I18) | ... AG19: =COUNTA(AG5:AG18)
A21: 留意事項: (1) 07:30-09:30 会場設営・テストと並行してHotel Mi→EXPOバス・Dorsett出発対応が必要。 (2) 10:00-11:45 Hall3(Opening/VIP Tour)とPeridot(受付・設営)に分かれ、VIP随行(宮木・児玉・荒木田)が抜ける間のPeridot側は藤中・田中・吉田のみ。 (3) Gala出発17:30はSC終了16:45の45分後で、撤収要員が不足。 (4)Day 1全体の前倒しについて、RT・SCは短縮不可のため、日本パビリオン開会式（GOHツアー内）の所要時間次第。 (6)【9/25決定】Day 1前倒しはRTの分割で対応: RT(1) 13:00-15:00、SC 15:15-16:15、RT(2)は29日09:00-09:30（TSは09:30据え置き）。これで17:30のGala出発まで75分の余裕。COSEM（9/29合同会議）と内閣府（9/25 16:30）に提案して確定。SC時の前方席はADRC（所長が説明）と内閣府。事務局席は前方寄り（ADRC席後方）に再配置。 (5)【9/28内閣府】10/28 16:00-16:30 MHA HQでバイ会談、16:30-16:40 MOC署名式（室長・御手洗参事官）。SC途中で退出、日本側司会は中根補佐。 (6)【9/29 JM6】名札65枚はSCDF部署から借用（ADRCが国旗ロゴ素材と名簿〈10/13〉を提供）。当日早朝設営の可否をExpoに確認中。AV見積SGD17〜19K。Zoom用カメラ1台はADRC持込で決定、2台運用（演台固定＋U字パン、Sylvia案）は未決。設営開始はExpo最早08:00とSylvia（JM6、要確認）、07:30入室は未承認。RT(1) 13:00-15:00＝Armenia〜Turkiye 22枠（各5分、Japanの直後に仙台市）、ADRC Opening 12:45-13:00＝Commissioner（tbc）・林副大臣・三浦センター長 各4分。 (追記 9/30 児玉) 内閣府: 林副大臣は Gala 欠席（日本企業との懇親会へ）、御手洗参事官が短時間出席。副大臣は 28 日 22:20 発で帰国。ACDR Opening は英語で挨拶、肩書 Deputy Minister for Disaster Management, Cabinet Office of Japan。 【10/1 内閣府スケジュール 9/28 版】林副大臣: Opening 挨拶→13:00 退席→13:10 SIDEX 視察（御手洗同行）→15:30 会場発→16:00 MHA バイ会談・16:30 MoC 署名→Gala 欠席（御手洗が代理）→22:20 発。RT Part 1 の日本発言＝中根補佐（荒木田 10/1 確定）。SC 議長＝中根補佐、前方席は宮木所長＋中根補佐。Japan 席は内閣府職員が常時 1 名。青木・起塚は VIP ツアー（日本パビリオン）対応。
A22: None
A23: 日本側サポート（神戸）※列はシンガポール時間、JSTは+1時間
A24: =人員一覧・判定!B18 | D24: Webinar起動・AI通訳・現地接続確認 | M24: ACDR Opening/RT: Q&A・コメント確認・AI通訳監視 | S24: SC: Zoom設定・Q&A確認
A25: =人員一覧・判定!B19 | D25: 録画準備 | M25: Opening/RT 録画・オンライン質疑取次 | S25: SC 録画
A26: =人員一覧・判定!B21 | M26: 録画(日英2台)ローカル保存
A27: =人員一覧・判定!B20 | D27: Webinarホスト・録画確認 | S27: SC Zoom設定
A28: ※WebinarとZoomはクラウド録画をバックアップとし、ローカルにも保存（2025年運用）。

Sheet 29Oct(Day2)
A1: 29 OCT 2026 (THU) Day 2: Technical Session / Closing / Field Trip (CDA) / SCDF Parade & Dinner ※28日はSCDF側がDorsett→会場を引率、29・30日はADRC側で誘導。パレード前はホテルで着替え後EXPOへ再移動（誘導要）
B3: 7:00 | D3: 8:00 | F3: 9:00 | H3: 10:00 | J3: 11:00 | L3: 12:00 | N3: 13:00 | P3: 14:00 | R3: 15:00 | T3: 16:00 | V3: 17:00 | X3: 18:00 | Z3: 19:00 | AB3: 20:00 | AD3: 21:00 | AF3: 22:00
A4: PROGRAM | D4: 会場準備（家具は前日のまま。AV・名札のみ）／登壇者集合・接続確認 | F4: Roundtable (2) 09:00-09:30（9/25案） | G4: Technical Session (Peridot) 09:30-11:30 | K4: Summary & Closing | L4: Lunch | N4: Field Trip: Civil Defence Academy 13:00 EXPO発 → 16:15 EXPO帰着 | Y4: SCDF Parade (Hall 4) | AB4: Parade Dinner (Garnet Room)
A6: =人員一覧・判定!B5 | G6: Tech Session | K6: Closing挨拶(Chairman) 11:51 | N6: Field Trip | Y6: Parade & Dinner
A7: =人員一覧・判定!B6 | G7: Tech Session | K7: Closing | N7: Field Trip | Y7: Parade & Dinner
A8: =人員一覧・判定!B7 | G8: Tech Session(内閣府随行) | K8: Summary発表(Executive Director) 11:45 | N8: Field Trip | Y8: Parade & Dinner
A9: =人員一覧・判定!B8 | D9: 会場準備 | G9: Tech Session(バイ会談調整) | N9: 事務局撤収(藤中と2名)/バイ会談 | Y9: Parade & Dinner
A10: =人員一覧・判定!B9 | D10: AV/Zoom準備／日本側と接続確認／RT(2) AV/Zoom 09:00- | G10: AV/Zoom運用 | K10: Summary/Closing進行/写真 | M10: Field Trip引率(バス) | Y10: Parade & Dinner
A11: =人員一覧・判定!B10 | D11: Mi→EXPO誘導／RT(2)運営(PIC)・ベル 09:00- | G11: Tech Session記録 | M11: Field Trip引率(バス) | V11: ホテル→EXPO誘導(パレード) | Y11: Parade & Dinner
A12: =人員一覧・判定!B11 | D12: 受付デスク/支払・清算 | N12: 事務局撤収(児玉と2名)/ホテル・バス精算 | Y12: Parade & Dinner
A13: =人員一覧・判定!B12 | D13: Dorsett→EXPO誘導(8-9)→受付デスク | M13: Field Trip名簿/バス点呼 | V13: ホテル→EXPO誘導(パレード) | Y13: Parade & Dinner
A14: =人員一覧・判定!B13 | D14: 登壇者集合・スライド確認／接続確認／RT(2) PC・スクリーン | G14: Tech Session運営(PIC) | N14: SIDEX展示/Japan Pavilion調整 | Y14: Parade & Dinner
A15: =人員一覧・判定!C14 | D15: Draft Summary仕上げ／RT(2)ノート | G15: Tech Sessionノート/Summaryスライド最終化 | K15: Summary(起草、発表は宮木所長) | N15: Field Trip | Y15: Parade & Dinner
A16: =人員一覧・判定!C15 | D16: 登壇者対応・進行確認 | G16: Co-Chair | N16: Field Trip | Y16: Parade & Dinner
A17: =人員一覧・判定!B16 | D17: Zoom/AI翻訳準備 | G17: Zoom・AI翻訳オペ/写真 | N17: Field Trip写真 or 事務局撤収 | Y17: Parade(写真)
A18: =人員一覧・判定!B17 | D18: Dorsett→EXPO誘導／RT(2)記録 | G18: カメラ、フロア対応 | N18: Field Trip | V18: ホテル→EXPO誘導(パレード) | Y18: Parade & Dinner
A19: 稼働人数(自動) | B19: =COUNTA(B5:B18) | C19: =COUNTA(C5:C18) | D19: =COUNTA(D5:D18) | E19: =COUNTA(E5:E18) | F19: =COUNTA(F5:F18) | G19: =COUNTA(G5:G18) | H19: =COUNTA(H5:H18) | I19: =COUNTA(I5:I18) | ... AG19: =COUNTA(AG5:AG18)
A21: 【9/25】29日は09:00からRT(2)（案）、続けてTS。日本側（中村・山口）はJST 10:00開始。11:30のサマリーに向け、TSは発表原稿から事前に概要案を作成（池田・Mizan→Gerry）、RTは当日作成。フィールドトリップの点呼・誘導担当は未定（要決定）。朝のHotel Mi／Dorsett→EXPO誘導が必要。 (1)TCのオンライン事前ブリーフィングは9/29が第一候補。 留意事項: (1) Technical SessionはMizan=Co-Chair、池田=PIC、荒木田=AV/Zoomで、塩見＝カメラとフロア担当。 (2) 11:45-12:00のSummary & ClosingはRT(前日)の要約が前提で、Gerryの執筆時間（Day1夜〜Day2朝）を確保する必要がある。 【9/29-30】Summary＝宮木所長（Executive Director）が発表、Gerry起草（28日夜〜29日朝）。Closing Remarks＝三浦センター長（Chairman）＋SCDF代表【TBC】。写真担当に荒木田を追加。TS登壇者: Google (Ms Sirada Boonkongchuen)、JAXA、BRIN (Dr Yenni Vetrita)、YI-Lab (Mr Pradip Khatiwada)、Uzbekistan（回答待ち）、内閣府枠（Spectee＋1社、15分）。RT(2) 09:00-09:30＝Uzbekistan・Viet Nam（各5分）→アドバイザー国→ADPC→ADB・AHA Centre・Google・オンライン（各3分）。進行シナリオ案0929参照。 【10/1 内閣府スケジュール 9/28 版】御手洗参事官: RT Part 2・TS・Closing 出席、Field Trip 参加、18:00 SIDEX 意見交換会→22:50 発。中根補佐: RT Part 2・TS・Closing、18:30 SCDF パレード・レセプション。青木・起塚: 18:00 SIDEX 意見交換会。30 日は中根・青木・起塚が 09:00 会場入り、22:20 発。
A22: None
A23: 日本側サポート（神戸）※列はシンガポール時間、JSTは+1時間
A24: =人員一覧・判定!B18 | D24: Webinar起動・AI通訳・現地接続確認 (JST9-10:30) | G24: TS/Closing: Q&A・コメント確認・AI通訳監視 | N24: Webinar終了処理・ログ回収
A25: =人員一覧・判定!B19 | D25: 録画準備 | G25: TS/Closing 録画・オンライン質疑取次 | N25: 録画データ整理・保存
A26: =人員一覧・判定!B21 | G26: 録画(日英)ローカル保存 ※仮置き
A27: =人員一覧・判定!B20 | D27: Webinarホスト・録画確認 ※仮置き
A28: ※WebinarとZoomはクラウド録画をバックアップとし、ローカルにも保存（2025年運用）。

Sheet 30Oct(Day3)
A1: 30 OCT 2026 (FRI) Day 3: SIDEX-ACDR Keynote / Panels / Exhibition Tour / Closing / 出発
B3: 7:00 | D3: 8:00 | F3: 9:00 | H3: 10:00 | J3: 11:00 | L3: 12:00 | N3: 13:00 | P3: 14:00 | R3: 15:00 | T3: 16:00 | V3: 17:00 | X3: 18:00 | Z3: 19:00 | AB3: 20:00 | AD3: 21:00 | AF3: 22:00
A4: PROGRAM | F4: Keynote & Panel 1 (Hall 3) | L4: Lunch | O4: Exhibition Tour | R4: Panel 2 | U4: Closing Ceremony | V4: 出発: 藤本 11/1 03:05(TR818、藤中・田中と同便)・塩見21:00(TG410)/荒木田22:20/北本23:55/吉田22:05/アゼルバイジャン23:15/インドネシア22:40/モンゴル23:55、三浦・韓国は10/31 01:20-01:35
A6: =人員一覧・判定!B5 | F6: Keynote/Panel1 | O6: Exhibition Tour/Panel2/Closing | AD6: 空港へ(SQ656 01:20)
A7: =人員一覧・判定!B6 | F7: Keynote/Panel1 | O7: Exhibition Tour/Panel2/Closing | AC7: 空港へ(SQ638 23:55)
A8: =人員一覧・判定!B7 | F8: Keynote/Panel1 | O8: Exhibition Tour/Panel2/Closing | V8: 内閣府見送り/総括
A9: =人員一覧・判定!B8 | F9: Keynote/Panel1 | O9: Exhibition Tour(誘導)/Panel2 | V9: 出発対応(Dorsett)・COSEM精算打合せ
A10: =人員一覧・判定!B9 | F10: Keynote/Panel1(リソース対応) | O10: Exhibition Tour/Panel2/Closing | V10: 総括・引継ぎ | AA10: 空港へ(NH844 22:20)
A11: =人員一覧・判定!B10 | D11: Dorsett→EXPO誘導 | F11: Keynote/Panel1 | O11: Exhibition Tour/Panel2 | V11: 参加者出発案内 | AB11: 空港へ(AY132 22:05)
A12: =人員一覧・判定!B11 | F12: 受付/清算 | O12: 会場(受付) | V12: Dorsett出発対応・支払
A13: =人員一覧・判定!B12 | D13: Dorsett→EXPO誘導 | F13: 受付 | O13: 会場(受付) | V13: Dorsett出発対応・送迎確認
A14: =人員一覧・判定!B13 | F14: Keynote/Panel1 | O14: Exhibition Tour誘導(Japan Pavilion) | R14: Panel2/Closing | V14: 機材撤収 | AE14: 空港へ(01:30発)
A15: =人員一覧・判定!C14 | F15: Keynote/Panel1/Summary最終化 | O15: Exhibition Tour/Panel2 | AE15: 空港へ(01:30発)
A16: =人員一覧・判定!C15 | F16: Keynote/Panel1 | O16: Exhibition Tour/Panel2
A17: =人員一覧・判定!B16 | F17: 写真/誘導 | O17: Exhibition Tour誘導/写真 | V17: 帰国準備→深夜空港へ（TR818 11/1 03:05発、藤中・田中と同便）
A18: =人員一覧・判定!B17 | F18: Keynote記録 | O18: 参加者誘導 | V18: 帰国準備→空港へ（TG410 21:00発。閉会16:50後すぐ移動）
A19: 稼働人数(自動) | B19: =COUNTA(B5:B18) | C19: =COUNTA(C5:C18) | D19: =COUNTA(D5:D18) | E19: =COUNTA(E5:E18) | F19: =COUNTA(F5:F18) | G19: =COUNTA(G5:G18) | H19: =COUNTA(H5:H18) | I19: =COUNTA(I5:I18) | ... AG19: =COUNTA(AG5:AG18)
A21: 留意事項: (1) 10/30夜〜10/31午前に出発が集中（メンバー国15組以上、役員3名）する。 【9/25】3日目はSIDEX側の運営。西川専門員がパネリスト。ACDR本体は29日11:30のサマリーで終了。
A23: 日本側サポート（神戸）※列はシンガポール時間、JSTは+1時間
A24: =人員一覧・判定!B18 | F24: （SIDEX配信はSCDF側）Webinar/Zoom終了処理・AI通訳ログ整理
A25: =人員一覧・判定!B19 | F25: 録画データ整理・保存（報告書・Highlights用）

Sheet 人員ギャップ分析
A1: 機能別 必要人数と充足状況（現時点の確定・見込メンバーでの判定）
A4: 機能 | B4: ピーク時間帯 | C4: 必要人数(目安) | D4: 現在の担当（確定・見込） | E4: 充足 | F4: ギャップ・リスク | G4: 対応案（追加要員の配置）
A5: 受付・参加者デスク（会場／公邸／ホテル） | B5: 10/26夕〜10/27（到着・名札配布）、10/28-29終日 | C5: 3 | D5: 藤中、田中（＋吉田は10/27夜・10/28午前のみ） | E5: △ | F5: ACDR2023は3名体制（堀池・藤中・田中）。今回は名札セットのQR配布(100-120名)と宿泊37室/泊の対応が加わる。 | G5: 藤本を3人目として配置（本人8/7『アドミサポート・会議補助なら可』）。または寺坂（デマケ上のリスト出力担当）。
A6: AV・PC・Zoom・AI翻訳オペレーション（現地側） | B6: 10/28 07:30-16:45、10/29 08:00-12:00 | C6: 2（うち1名は現地専任） | D6: 現地: 荒木田、池田／日本側: 中村（Zoom・AI通訳設定・Q&A確認）、山口（録画・オンライン質疑） | E6: △ | F6: Zoomホスト・AI通訳監視・Q&A・録画は2025年同様に神戸側、現地の負荷は『会場AVとAI通訳端末の物理接続・トラブル一次対応』に絞られる。Webinar進行・機材・スクリーンをホスト国（SCDF/COSEM）側が担えるか確認中。会場は横長レイアウトへ変更交渉中、レイアウト表を次回までに作成 | G6: 現地の一次対応は藤本を推奨。会場AVはSCDF側スタッフに操作依頼できるか9月合同会議で確認。日本側と現地の連絡手段（WhatsApp等）と時差1時間の運用ルールを事前に決める。
A7: セッション運営（RT・Tech Session） | B7: 10/28 13:00-15:30、10/29 09:30-12:00 | C7: 3（PIC・Co-Chair・フロア） | D7: RT: 吉田・Gerry／TS: Mizan(Co-Chair)・池田 | E7: △ | F7: TSはMizanが登壇側に回ると、登壇者6名の誘導・時間管理・Q&A取次を行うフロア担当が池田1名。 | G7: 塩見（承諾済み）をRT/TSの記録・フロア補助に配置。
A8: 写真・動画記録（Highlight Movie含む） | B8: 会期中全日 | C8: 1 | D8: 藤本（撮影を主担当、児玉 9/4） | E8: ○ | F8: 藤本が撮影主担当で本人承諾済み（9/4）。COSEM側の公式カメラマンの有無と集合写真の場所・時刻はCOSEM協議事項 | G8: 撮影計画（Opening集合写真、RT、TS、公邸、パレード）を作成。ハイライト動画の編集場所と素材受渡しをCOSEMと確認
A9: Field Trip引率（CDA、バス点呼） | B9: 10/29 13:00-17:15 | C9: 2-3 | D9: 荒木田、吉田（デマケ）、田中（名簿） | E9: ○ | F9: 引率自体は足りるが、同時刻に会場撤収・Day3準備・バイ会談が残る（児玉・藤中・池田）。 | G9: 現状維持。塩見参加で引率を1名追加可能。
A10: 到着・出発対応（空港・ホテル） | B10: 10/26 15:00-24:00、10/27午前、10/30夜〜10/31午前 | C10: 2 | D10: 藤中、田中（COSEMが空港送迎） | E10: △ | F10: 10/26は宮木・児玉が前日（10/25夜）入りしているためDorsett到着対応を分担できる。一方10/31朝は宮木・児玉（06:35発）、池田・Gerry（深夜発）も帰国し、見送り・清算は藤中・田中の2名のみ。 | G10: 10/26夕方は宮木・児玉・藤中・田中でDorsett対応（藤本は17:30着で夕方から合流可、塩見は19:55着）。10/31朝は藤中・田中の2名で見送り・清算。
A11: オンライン配信・録画・Q&A（日本側） | B11: 10/28 12:30-16:45、10/29 08:00-12:00（SGT） | C11: 2＋バックアップ | D11: 中村（Zoom Webinar/Meeting設定・ホスト、AI通訳設定・監視、Q&A確認）、山口（録画クラウド＋ローカル、オンライン質疑）／寺坂（録画日英）、伊達（ホスト確認） | E11: ○ | F11: 2025年はSC・ACDRとも神戸側でWebinar設定・録画・Q&A確認を行い問題なし。今回はAI通訳が加わるため、事前リハーサル（10/26-27）で現地端末との接続確認が必要。 | G11: 10/26-27に中村・山口が現地（荒木田・池田）と接続テスト。寺坂・伊達のバックアップ要否を本人に確認。
A12: 参加者誘導（Dorsett⇔EXPO、パレード前） | B12: 10/29・30 朝 08:00-09:00、10/29 17:00-18:30 | C12: 2 | D12: 田中、吉田、塩見 | E12: △ | F12: 9/4打合せ: SCDFの引率は28日のみ。29・30日朝と、パレード前（ホテルで着替え後にEXPOへ再移動、渋滞で遅れるリスク）の誘導はADRC側で必要。参加者リストを作って担当を割り当てる（荒木田アクション） | G12: Field Trip参加者リストを基に誘導担当を確定。バス・タクシーの手配はCOSEMと調整。ドレスコードを事前周知
A13: 今後のスケジュール（9/4打合せ）
A14: ・9/12: Google登壇者の回答期限。TS登壇者（JAXA確定、内閣府枠でJapan Pavilion出展企業2社程度、モデレーター代替候補、Mizan=Co-Chair案）を荒木田が池田と確認しインビテーション発出
A15: ・9月下旬: 次回所内打合せ（会場レイアウト表、COSEMとの役割分担案、動態表更新版を提示）
A16: ・10/9(金) 理想、遅くとも10/13-16: ロジ最終版・アジェンダ最終ドラフト・SC書類を完成、メンバー国・参加者へ送付（藤中）
A17: ・10/13: Final Announcement（開催2週間前）
A18: ・10/26-27: 現地入り、日本側との接続・運用テスト、27日午前に全員で会場下見
A19: ・広報: 内閣府・県庁記者クラブへのプレスリリース（管理部と宮木）、神戸新聞記者（7月来訪、ネパール取材）へ案内（荒木田）
A20: ・9/25 所内打合せ: RT分割案（RT(1) 28日13:00-15:00、SC 15:15-16:15、RT(2) 29日09:00-09:30）をCOSEM（9/29合同会議）・内閣府へ提案。10/9全確定、10/13 Final Announcement。
A21: ・9/25 後の確認事項: ①Mizanのフライト（唯一未確定）、②フィールドトリップの点呼・誘導担当、③27日の前日設営に残る者（会場の前日利用可能時刻次第）、④事務局席の前方再配置、⑤27日午前の大使表敬（足立氏と調整）。

Sheet COSEM協議事項
A1: COSEM/SCDFとの協議事項（役割分担・ドレスコード・会場・導線・記録・事務・プログラム） as of 2026/9/30 v2_93
A2: 協議の場: 第5回合同会議（9/15、オンライン。Sylvia 6/18・内閣府8/31資料で確認）＋メール＋Zoom（9/4 荒木田）。5月の事前協議チェックリストで「未対応」のまま残る項目を再掲し、9/4所内打合せで出た論点を加えた。合意内容はGI改訂（Final Announcement 10/13前）と運営マニュアルに反映する。状態: 未協議／協議中／合意。
A4: No. | B4: 区分 | C4: 項目 | D4: ADRC側の現状認識・案 | E4: COSEM/SCDFに確認・合意したいこと | F4: 根拠 | G4: 希望期限 | H4: ADRC担当 | I4: 状態
A5: A1 | B5: 役割分担 | C5: 28日朝の会場・NW最終テスト | D5: 荒木田・池田が07:30から実施し、日本側（中村・山口）と接続確認。9/24メールで07:30入室の可否をSylvia氏に照会中。 | E5: 開始時刻（7:30か8:00）、COSEM/SCDF側の立会い者とAV操作者、演台・客席・事務局部屋での実測、衛星データ/ARデモの再生確認／前日（27日）に会場へ入れる時刻（設営・テスト可否） | F5: 5月CL 1-IT（要確定）、9/4打合せ | G5: 第5回合同会議（9/15） | H5: 荒木田・池田 | I5: 協議中
A6: A2 | B6: 役割分担 | C6: Webinar／Zoom／AI通訳ツールの運用 | D6: 日本側: 中村（Zoomホスト・AI通訳設定・Q&A確認）、山口（録画・オンライン質疑）。現地一次対応: 藤本。ホスト国側で進行・機材を担えるなら望ましい（9/4 荒木田） | E6: 会場PCへの接続方法、スクリーン切替の担当、翻訳ツール（ポケトーク等）のURL/QRの掲示方法、WhatsApp参加者グループの共有、ハイブリッド配信の範囲（RT・TS・SC） | F6: 5月CL 2「記録・メディア 未対応」「使用言語 未対応」、GI（AI翻訳ツール試行）、9/4打合せ | G6: 第5回合同会議（9/15） | H6: 荒木田・中村 | I6: 未協議
A7: A3 | B7: 役割分担 | C7: モデレーター体制 | D7: TSモデレーター: LTC Chen Yong Kai, Deputy Commander, 3rd SCDF Division（Sylvia 9/17）。ADRC側Co-Chair（所内版=Mizan）。予備のLTC Adrianはプログラム・レセプションに含めない。 | E7: 9/29（代替9/30、10/8、10/9）のオンライン事前ブリーフィング日程（MizanがSylvia氏と設定）。RTのSCDFモデレーターは別途。 | F7: Sylvia 9/17 WhatsApp、9/18週次 | G7: 9/19（登壇者確定） | H7: 荒木田・Mizan・池田 | I7: 合意
A8: A4 | B8: 役割分担 | C8: 受付・名札（QRセット） | D8: QR付き名札セットは27日の公邸レセプションで手渡し。会場受付は藤中・田中（＋藤本）。当日参加者への対応方針は未定。事前に詳細を渡せばCOSEMがADRC招待者のSIDEX登録を裏で行いパスを印刷（Sylvia 8/17 WhatsApp） | E8: 会場受付のSCDF/ADRCスタッフ配置、QR読取機の台数・場所、公邸で受け取れなかった人への当日発行、当日飛び込み参加の扱い、会議セット（バッグ等）の配布場所 | F8: 5月CL 2「事前登録」「受付対応 未対応」「参加者サポート 未対応」 | G8: 第5回合同会議（9/15） | H8: 田中・藤中 | I8: 未協議
A9: A5 | B9: 役割分担 | C9: 事務局部屋（28-29日） | D9: 28日朝にGerry・Mizan・塩見が設営。29日終了後に児玉・藤中が撤収（27日と30日は部屋なし）。Tourmaline 207・Peridot 202-205はCOSEM負担で無償（Sylvia 8/25 WhatsApp） | E9: 広さ・施錠・複合機・延長コード・水、28日朝の入室可能時刻、30日の荷物置き場 | F9: 5月CL 1「事務局部屋 詳細未対応」、9/4打合せ | G9: 第5回合同会議（9/15） | H9: 藤中 | I9: 未協議
A10: A6 | B10: 役割分担 | C10: 参加者の引率（ホテル⇔EXPO） | D10: 28日はSCDFが Dorsett→会場を引率。29・30日は引率なし（9/4 藤中）→ADRC側で誘導（田中・吉田・塩見）。パレード前はホテルで着替えてEXPOへ再移動。Field Trip後のEXPO帰着は17:00、パレードは18:00着席・GOH 18:30到着（Sylvia 8/26）→ホテルで着替える時間は約1時間 | E10: 29・30日朝のシャトル時刻とバス台数、Hotel Mi→EXPO朝バス、パレード前のホテル→EXPO便と出発時刻、Gala出発（17:30 Dorsett）の集合方法 | F10: 5月CL 3「導線」、9/4打合せ、Agenda 0805r | G10: 第5回合同会議（9/15） | H10: 田中 | I10: 協議中
A11: A7 | B11: 役割分担 | C11: Field Trip（CDA）の運行 | D11: 荒木田・吉田が引率、田中が名簿・点呼。最新版は13:00 EXPO発・16:15帰着（9/18 WhatsApp配布）。ADRC Web用アジェンダv2は13:00-16:15で整合。 | E11: ヘルメット・ベスト貸出、服装要件（9/6〜未回答）、休憩・水分、渋滞時の対応、登壇者の同行可否（空きがあれば可・main guest list優先） | F11: WhatsApp 9/18、Sylvia 9/18 | G11: 第5回合同会議（9/15） | H11: 荒木田・吉田 | I11: 協議中
A12: A8 | B12: 役割分担 | C12: 写真・ビデオ・集合写真 | D12: 藤本が撮影主担当（承諾済み）。ハイライト動画は閉会時上映の想定。撮影ポイントは27日公邸レセプションとCDA視察（ひな壇型）で合意（WhatsApp 8/14） | E12: COSEM公式カメラマンの有無、集合写真の場所（Hall 3入口等）と時刻（Day1 Opening後）、素材の受渡しフロー、動画編集の場所 | F12: 5月CL 2「写真・ビデオ 未対応」「集合写真 未対応」 | G12: 第5回合同会議（9/15） | H12: 藤本・Gerry | I12: 未協議
A13: A9 | B13: 役割分担 | C13: バナー・バックドロップ・サイン | D13: 物理バナーで確定（スクリーンはビデオ会議で使用）。COSEM/SCDFのデザイン案を9/24に受領し、ADRCは同案で可と回答。修正依頼2点: 上段ロゴ・国旗の上下中心線を揃え両国旗を同サイズに、正式名称「Asian Conference on Disaster Reduction 2026」を大きく。【9/25】期間表記は28-29ではなくACDR2026全体の「27-30 October 2026」に訂正を申入れ（会場名Singapore Expoは維持）。内閣府の確認（9/25午後）後に確定。 | E13: 寸法（EXPO照会中）、修正版デザイン、高解像度ロゴ・国旗データの要否、設置位置（ステージ床かバックドロップか） | F13: WhatsApp 9/18〜9/24、荒木田→藤本 9/18 | G13: 9月末 | H13: 荒木田・藤本 | I13: 協議中
A14: A10 | B14: 役割分担 | C14: 会場レイアウト（Peridot） | D14: Peridot 201-203で確定（28日終日＋29日午前）。EXPO縮尺図（動線2.60m/1.50m/1.30m）を9/22受領。ADRCは9/24メールで「U字28席（12+4+12、ホスト6＋メンバー国22）＋両サイド12席×2列＋教室型8席×4列＋シアター席」を提案し、EXPOの作図を依頼。【9/25】U28=最大23か国＋SG1＋日本1＋ADRC1（＋NZ1・ADPC1、入らなければ2列目）。事務局席は前方寄り（ADRC席後方）に再配置。実スケール確認後に電源・マイクを確定。 | E14: EXPOによる再作図、スクリーン位置の図示、前方エリアのセッション別バリエーション（開会・RT・SC・TS・閉会）はADRCが作成 | F14: Sylvia 9/18 WhatsApp・9/22メール、荒木田 9/24メール | G14: 10/1 第6回合同会議 | H14: 荒木田・池田 | I14: 協議中
A15: A11 | B15: 役割分担 | C15: バイ会談スペース・VIP控室 | D15: 宮木・児玉が内閣府・COSEMとの調整を担当（張り付きはしない） | E15: 小部屋・ブースの予約ルール、内閣府随行の控室、水の配置 | F15: 5月CL 1「バイ会談 未対応」「VIP控室 未対応」 | G15: 第5回合同会議（9/15） | H15: 宮木・児玉 | I15: 未協議
... A64: J60 | B64: 会場・機材 | C64: 会場バナーのデザイン案 | D64: Sylvia 9/30 → 荒木田に確認依頼。案: 上段 SG国旗・SCDF・COSEM・ADRC ロゴ・日本国旗、下段「SIDEX-ACDR 2026 in conjunction with FiSAC」ロゴ＋「ASIAN CONFERENCE ON DISASTER REDUCTION 2026 / 27-30 October 2026 | Singapore Expo」。会期表記はアジェンダ（27-30 Oct）と一致。内閣府ロゴ・名称なし（記者発表では内閣府が主催）→ 児玉経由で内閣府に確認。ADRC ロゴは公式データを送付。 【9/30 児玉】内閣府ロゴは不要（打合せと大使館で確認済）。→ Sylvia に「デザイン了承、ADRC ロゴ高解像度データを送付」と返答。 | E64: ADRC ロゴ公式データの送付、寸法（卓前面布バナー／A型スタンド） | F64: WhatsApp 9/30 | G64: 10/3 | H64: 荒木田・児玉 | I64: 合意
B66: 凡例
C67: 未協議（COSEM/SCDFにまだ提示していない）
C68: 協議中（提示済み・回答待ち）
C69: 合意
B71: 集計
B72: 未協議 | C72: =COUNTIF(I5:I64,"未協議")
B73: 協議中 | C73: =COUNTIF(I5:I64,"協議中")
B74: 合意 | C74: =COUNTIF(I5:I64,"合意")

Sheet 参加者到着・出発(9月24日更新)
A1: メンバー国等 到着・出発予定（ホテル部屋数検討用リスト_tt.xlsx Dorsettシート, as of 2026/8/25-28）
A2: ※TBDは招待済みで人選未定。DS=Dorsett自己負担。到着時刻はCOSEM送迎・Dorsett受付配置の検討用。
A3: 【9/4打合せ時点の登録状況】メンバー国15か国（日本・シンガポール除く。含めると17か国でSC定足数を確保）、現地登録42名、オンライン3名。新規: バングラデシュ、パキスタン2名、PNG2名、フィジー3名、カンボジア3名、韓国3名予定（登録未）、NZ（アドバイザー）3名。ウズベキスタン2名（リソース1＋メンバー1）は回答待ち。インドネシア環境省の扱い（メンバー国か）は要確認。フィリピン・タイ・ブルネイの追加で約20か国の見込み。到着は26日と27日午前に集中させる方針だが、14時台着（バングラデシュ等）はタクシー送迎の想定。 【9/24更新】9/17以降の登録: ブルネイ1名（9/20）、韓国3名（9/21）、COSEM Fabian Tan氏（9/24）、一般オンライン1名。タイはDDPMがPrasong Thammapala氏を指名予定（9/22、ADRCは1名分負担と回答）。タジキスタン・ウズベキスタンは9/24にWhatsAppで再リマインド（両国ともビザ要）。ウズベキスタンは連絡が取れ、2名を選出・登録予定（事務局が案内メールを再送）。 【9/25 藤中の登録リスト】メンバー国20か国36名（＋日本・タイ・ウズベキスタンで23か国）、NZ3名、一般22名（ADPCは2→4名予定）、リソース2名追加、ADRC12名。現地61名→最大83名。詳細は「参加者登録状況(9-25)」シート。
A4: 国・組織 | B4: 氏名 | C4: 到着日 | D4: 到着時刻 | E4: 出発日 | F4: 出発時刻 | G4: 便名(到着/出発) | H4: 宿泊 | I4: Field Trip | J4: 備考
A5: モルディブ | B5: Hassan Hisan (Chief Executive, NDMA) | C5: 10/27 | D5: 07:15 | E5: 10/31 | F5: 10:25 | G5: ― | H5: D | I5: Yes | J5: Halal
A6: アルメニア | B6: Syuzanna Vardazari Kakoyan | C6: 10/27 | D6: 08:45 | E6: 11/1 | F6: ― | G6: TK208/TK209 | H6: D(+10/31 DS) | I6: Yes | J6: 本人希望で1泊延長
A7: アゼルバイジャン | B7: Zamanov Niyazi | C7: 10/26 | D7: 17:40 | E7: 10/30 | F7: 23:15 | G7: TK335/TK54 | H7: D | I7: Yes | J7: Halal
A8: アゼルバイジャン | B8: Rustamzade Kamran | C8: 10/26 | D8: 17:40 | E8: 10/30 | F8: 23:15 | G8: TK335/TK54 | H8: DS | I8: Yes | J8: Halal
A9: トルコ | B9: Pehlivan Ali Hamza (Governor/Head of AFAD) | C9: 10/27 | D9: 08:45 | E9: 10/31 | F9: 10:25 | G9: ―/TK209 | H9: D | I9: Yes | J9: Halal
A10: トルコ | B10: Yaman Muhammet Maruf | C10: 10/27 | D10: 08:45 | E10: 10/31 | F10: 10:25 | G10: ―/TK209 | H10: DS | I10: Yes | J10: Halal
A11: モンゴル | B11: Nyambayar Tsedev (Director, NEMA) | C11: 10/26 | D11: 21:55 | E11: 10/30 | F11: 23:55 | G11: CA969/CA970 | H11: D | I11: Yes | J11: 中国国際航空(北京経由)
A12: フィジー | B12: Naipolioni Dabea Boseiwaqa (Director, NDRMO) | C12: 10/26 | D12: 21:35 | E12: 10/31 | F12: 13:40 | G12: ― | H12: D | I12: No | J12: 【9/25】フライト手配のやり取りが進まず参加不透明。JICA櫻井氏にサポート依頼中
A13: スリランカ | B13: Maj.Gen.(Retd.) Kotuwegoda (DG, DMC) | C13: 10/27 | D13: 08:10 | E13: 10/31 | F13: 09:40 | G13: ― | H13: D | I13: No
A14: マレーシア | B14: Ezrin Rozani Bin Rosli (NADMA) | C14: 10/27 | D14: 12:20 | E14: 10/31 | F14: 12:45 | G14: ― | H14: D(10/27-) | I14: Yes | J14: Halal
A15: 韓国 | B15: Byungim So (MOIS) | C15: 10/26 | D15: 20:25 | E15: 10/31 | F15: 01:35 | G15: ― | H15: D | I15: No
A16: 韓国 | B16: Kim Ingeon（Deputy Director）、Lee Taekgeon（Assistant Director）、Song Hana（Deputy Director）いずれもMOIS、9/21登録 | C16: 10/26 | D16: 20:25 | E16: 10/31 | F16: 01:35 | G16: ― | H16: DS | J16: 9/25: So氏を含め4名で確定（藤中リスト）
A17: ベトナム | B17: Truong Son Nguyen（DDG）、Ba Nam Nguyen、Vu Thuy Duong | C17: 10/26 | D17: 17:20 | E17: 10/31 | F17: 12:35 | G17: ― | H17: D/DS | J17: 9/25: 3名
A18: ウズベキスタン | B18: 2名（登壇者1名＋一般1名）を選出・登録予定（9/24-25） | C18: 10/27 | D18: 08:45 | E18: 10/31 | F18: 10:25 | G18: ― | H18: D×2 | J18: 9/24 WhatsApp再リマインドで連絡が取れ、2名の選出と登録を行う予定と確認。事務局からわかりやすい案内メールを再送するよう依頼済み。ビザ要（外交旅券のみ免除）、申請9/26〜。TS登壇者は10/2締切
A19: フィリピン | B19: TBD ×2 | C19: 10/26 | D19: 18:00 | E19: 10/31 | F19: 12:10 | G19: ― | H19: D/DS
A20: ブルネイ | B20: Rina Nurhafizah Binti Abdul Rani（Senior DM Officer, NDMC）＋1名の可能性 | C20: 10/27 | D20: 14:30 | E20: 10/31 | F20: 09:00 | G20: ― | H20: D/DS | J20: 9/25: 1名登録、もう1名増える可能性
A21: ブータン | B21: Tshering Dorji（Senior Program Officer, MoHA） | C21: 10/26 | D21: 19:30 | E21: 11/1 | F21: 12:30 | G21: ― | H21: D
A22: PNG | B22: Lusete Laso Mana（DG, NDC）、Roland Kopeap（Research Officer） | C22: 10/26 | D22: 19:30 | E22: 10/31 | F22: 20:40 | G22: ― | H22: D | J22: 9/25: 初めて2名参加
A23: タイ | B23: Prasong Thammapala（Director, NDWC）予定 | C23: 10/27 | D23: 14:50 | E23: 10/31 | F23: 12:25 | G23: ― | H23: D(10/27-) | I23: No | J23: 【9/25】DDPMからの連絡途絶。ヘッドは旅程のみでホテル予約なし。来訪は不確実
A24: カンボジア | B24: Norith Ma（Deputy Secretary-General, NCDM） | C24: 10/26 | D24: 18:00 | E24: 10/31 | F24: 12:45 | G24: ― | H24: D | J24: 9/1登録あり
A25: ミャンマー | B25: Mar Kay Thi Hla（Director, DDM） | C25: 10/27 | D25: 15:10 | E25: 10/31 | F25: 13:45 | G25: ― | H25: D(10/27-)
A26: インドネシア | B26: （メンバー国としての登録なし。環境省 Alfarizi Zaky M. は一般扱い。BNPBは1回確認し返答なければ支援対象外） | C26: 10/27 | D26: 11:20 | E26: 10/30 | F26: 22:40 | G26: ― | H26: D(10/27-)
A27: パキスタン | B27: Muhammad Tahir Iqbal Malik（ED）、Shahzad Malik Saleem（Senior Director） | C27: 10/27 | D27: 11:15 | E27: 10/31 | F27: 12:25 | G27: ― | H27: D(10/27-) | J27: 9/25: 2名
A28: インド | B28: Awasthi Ashutosh、Govind Prasad Uniyal、Krishnan B Sandeep（MHA） | C28: 10/26 | D28: 18:00 | E28: 10/31 | F28: 16:40 | G28: ― | H28: D+DS×2
A29: 内閣府（日本） | B29: 林副大臣・御手洗参事官・中根補佐（27 日 SQ 08:30 HND 発 15:00 SIN 着）、青木補佐・起塚（26 日 16:40 HND 発 23:25 SIN 着）。出発: 林 28 日 22:20、御手洗 29 日 22:50、中根・青木・起塚 30 日 22:20。宿泊: 林・御手洗 Royal Plaza on Scotts、中根・青木・起塚 Dorsett（内閣府スケジュール 9/28 版、Sylvia 名簿 10/1） | C29: 10/26・10/27 | D29: 23:25（青木・起塚）／15:00（林・御手洗・中根） | E29: 10/28・29・30 | F29: 22:20（林）／22:50（御手洗）／22:20（中根・青木・起塚） | G29: ― | H29: Royal Plaza on Scotts×2（林・御手洗）、Dorsett×3（中根・青木・起塚） | J29: CV準備中。英語サポート要
A30: リソース | B30: TSスピーカー: BRIN Yenni Vetrita氏（GA828 27日着で打診）、YI-Lab Pradip Khatiwada氏（Air India経由かSQ直行かアドミ確認中）、JAXA（人選中・自己負担）、Google Sirada氏（自己負担）、ウズベキスタン TBD、内閣府 TBD | C30: 10/27 | D30: ― | E30: 10/31 | F30: ― | G30: ― | H30: D×2 | J30: 藤本が見積取得中（9/18）。BRIN復路はMizan経由で照会中
A31: 観察者・一般 | B31: ADPC 2名（Aslam Perwaiz ED、Weerapon）→4名予定、AHA Centre Krishna Putra Tanaja、JICAフィジー櫻井、東北大小野教授、仙台市4名（高橋副市長ほか）、Mercy Malaysia、JBP、近畿大、三重大、Oxfam、ADB、UNHAS、インドネシア環境省、大学関係ほか計22名 | C31: ― | D31: ― | E31: ― | F31: ― | G31: ― | H31: 自己手配 | J31: 昼食提供対象
A32: タジキスタン | B32: TBD | C32: ― | D32: ― | E32: ― | F32: ― | G32: ― | H32: D | I32: ― | J32: 9/24 WhatsApp再リマインド。ビザ要
A33: SIDEXリソース（COSEM負担） | B33: 西川 悟 JICA Senior Advisor | C33: ― | D33: ― | E33: ― | F33: ― | G33: ― | H33: COSEM手配 | I33: ― | J33: 3日目SIDEXイベントの登壇者。Welcome Dinner招待のためリソース登録（児玉→藤本 9/24）。費用はすべてCOSEM持ち。スピーカーディナーと重複の可能性
A34: COSEM | B34: Fabian Hwi Min Tan（Deputy CEO, Operations） | C34: ― | D34: ― | E34: ― | F34: ― | G34: ― | H34: ― | I34: ― | J34: 9/24登録（現地参加）
A36: Dorsett確保数（8/28にCOSEMへ通知）: 10/26 29室、10/27-30 37室/泊、10/31 2室、計180 room nights。9/28に10%リリース可、以後100%課金。

Sheet 参加者登録状況(9-25)
A1: ACDR2026 参加者登録状況（藤中の登録リスト 2026/9/25 所内打合せ配布、マスター登録ベース）
A2: 区分: メンバー国20か国36名（＋日本・タイ・ウズベキスタン＝23か国の見込み）／アドバイザー国NZ 3名／一般22名（リソース2名・ADPC2名が追加予定→現地71名）／ADRC 12名（現地73名、最大83名）／オンライン 一般7名・ADRC4名
A4: 区分 | B4: No. | C4: 氏名 | D4: 国 | E4: 役職 | F4: 部署 | G4: 組織 | H4: 参加形態 | I4: 備考（9/25所内打合せ）
A5: メンバー国 | B5: 1 | C5: Syuzanna Vardazari Kakoyan | D5: Armenia | E5: Head of the Department for Public Outreach | F5: Department for Public Outreach | G5: Regional Survey for Seismic Protection of MIA | H5: Onsite (face-to-face)
A6: メンバー国 | B6: 2 | C6: Rustamzade Kamran | D6: Azerbaijan | E6: Head of Sector | F6: Protocol | G6: Ministry of Emergency Situations | H6: Onsite (face-to-face)
A7: メンバー国 | B7: 3 | C7: Zamanov Niyazi | D7: Azerbaijan | E7: Chief of Main Department | F7: The Main Department for Organization of Activities on Civil Defense | G7: Ministry of Emergency Situations | H7: Onsite (face-to-face)
A8: メンバー国 | B8: 4 | C8: A B M Shafiqul Haider | D8: Bangladesh | E8: Additional Secretary | G8: Ministry of Disaster Management and Relief | H8: Onsite (face-to-face)
A9: メンバー国 | B9: 5 | C9: Tshering Dorji | D9: Bhutan | E9: Senior Program Officer | F9: Department of Local Governance and Disaster Management | G9: Mininstry of Home Affairs | H9: Onsite (face-to-face)
A10: メンバー国 | B10: 6 | C10: Rina Nurhafizah Binti Abdul Rani | D10: Brunei Darussalam | E10: Senior Disaster Management Officer | F10: Operations Division | G10: National Disaster Management Centre | H10: Onsite (face-to-face) | I10: もう1名増える可能性
A11: メンバー国 | B11: 7 | C11: Norith Ma | D11: Cambodia | E11: Deputy Secretary-General | F11: Secretariat-General of NCDM | G11: National Committee For Disaster Management (NCDM) | H11: Onsite (face-to-face)
A12: メンバー国 | B12: 8 | C12: Naipolioni Dabea Boseiwaqa | D12: Fiji | E12: Director | G12: National Disaster Risk Management Office | H12: Onsite (face-to-face) | I12: フライト手配が進まず参加不透明（櫻井氏に依頼）
A13: メンバー国 | B13: 9 | C13: Awasthi Ashutosh | D13: India | E13: Deputy Director | F13: Disaster Management Division | G13: Ministry of Home Affairs | H13: Onsite (face-to-face)
A14: メンバー国 | B14: 10 | C14: Govind Prasad Uniyal | D14: India | E14: Deputy Inspector General | F14: Integrated Control Room for Emergency Response | G14: MHA (GoI) | H14: Onsite (face-to-face)
A15: メンバー国 | B15: 11 | C15: Krishnan B Sandeep | D15: India | E15: Assistant Director General | F15: Directorate of Civil Defence, Disaster Management Division | G15: Ministry of Home Affairs | H15: Onsite (face-to-face)
A16: メンバー国 | B16: 12 | C16: Syasompheng Phonesavanh | D16: Lao PDR | E16: Director | F16: Director of Disaster Prevention Division | G16: Social Welfare Departments | H16: Onsite (face-to-face)
A17: メンバー国 | B17: 13 | C17: Ezrin Rozani Bin Rosli | D17: Malaysia | E17: Senior Assistant Director | F17: Logistics | G17: National Disaster Management Agency Malaysia | H17: Onsite (face-to-face)
A18: メンバー国 | B18: 14 | C18: Hassan Hisan | D18: Maldives | E18: Chief Executive | G18: National Disaster Management Authority | H18: Onsite (face-to-face)
A19: メンバー国 | B19: 15 | C19: Nyambayar Tsedev | D19: Mongolia | E19: Director | F19: Fire Department | G19: National Emergency Management Agency of Mongolia | H19: Onsite (face-to-face)
A20: メンバー国 | B20: 16 | C20: Mar Kay Thi Hla | D20: Myanmar | E20: Director | F20: Department of Disaster Management | G20: Ministry of Social Welfare, Relief and Resettlement | H20: Onsite (face-to-face)
A21: メンバー国 | B21: 17 | C21: Muhammad Tahir Iqbal Malik | D21: Pakistan | E21: Executive Director | F21: Technology | G21: National Disaster Management Authority, Pakistan | H21: Onsite (face-to-face)
A22: メンバー国 | B22: 18 | C22: Shahzad Malik Saleem | D22: Pakistan | E22: Senior Director | F22: Disaster Risk Reduction | G22: National Disaster Management Authority | H22: Onsite (face-to-face)
A23: メンバー国 | B23: 19 | C23: Lusete Laso Mana | D23: Papua New Guinea | E23: Director General | F23: Executive Division/National Disaster Centre | G23: National Disaster Centre | H23: Onsite (face-to-face)
A24: メンバー国 | B24: 20 | C24: Roland Kopeap | D24: Papua New Guinea | E24: Research Officer | F24: Office of the Minister | G24: National Disaster Centre | H24: Onsite (face-to-face)
A25: メンバー国 | B25: 21 | C25: Byungim So | D25: Republic Of Korea | E25: Assistant Director | F25: Disaster Management Policy Division | G25: Ministry of the Interior and Safety | H25: Onsite (face-to-face)
A26: メンバー国 | B26: 22 | C26: Hana Song | D26: Republic of Korea | E26: Deputy Director | F26: Climate Disaster Management Division | G26: Ministry of the Interior and Safety | H26: Onsite (face-to-face)
A27: メンバー国 | B27: 23 | C27: Ingeon Kim | D27: Republic of Korea | E27: Deputy Director | F27: Disaster and Safety Data Division | G27: Ministry of the Interior and Safety | H27: Onsite (face-to-face)
A28: メンバー国 | B28: 24 | C28: Taekgeon Lee | D28: Republic of Korea | E28: Assistant Director | F28: Agriculture, Livestock and Marine Disaster Response Division | G28: Ministry of the Interior and Safety | H28: Onsite (face-to-face)
A29: メンバー国 | B29: 25 | C29: Alan Chow | D29: Singapore | E29: Director | F29: Planning & Organisation Department | G29: Singapore Civil Defence Force | H29: Onsite (face-to-face)
A30: メンバー国 | B30: 26 | C30: Fabian Hwi Min Tan | D30: Singapore | E30: Deputy Ceo | F30: Operations Group | G30: Cosem Safety & Security Services Pte Ltd | H30: Onsite (face-to-face)
A31: メンバー国 | B31: 27 | C31: Sirada Boonkongchuen | D31: Singapore | E31: Product Partnership, Google Search & Gemini | F31: Product | G31: Google | H31: Onsite (face-to-face)
A32: メンバー国 | B32: 28 | C32: Yap Eric | D32: Singapore | E32: Commissioner | G32: Singapore Civil Defence Force | H32: Onsite (face-to-face)
A33: メンバー国 | B33: 29 | C33: Yong Kai Chen | D33: Singapore | E33: Deputy Commander | F33: 3Rd Scdf Division | G33: Singapore Civil Defence Force | H33: Onsite (face-to-face)
A34: メンバー国 | B34: 30 | C34: Kachchakaduge Nipul Sampath Kotuwegoda | D34: Sri Lanka | E34: Director General | G34: Disaster Management Centre | H34: Onsite (face-to-face)
A35: メンバー国 | B35: 31 | C35: Orhan Tatar | D35: Turkiye | E35: Director General | F35: Earthquake and Risk Reduction | G35: Disaster and Emergency Management Presidency / AFAD | H35: Onsite (face-to-face)
A36: メンバー国 | B36: 32 | C36: Pehlivan Ali Hamza | D36: Turkiye | E36: Governor / Head of AFAD | G36: Republic of Turkiye - Ministry of Interior - Disaster and Emergency Management Authority (AFAD) | H36: Onsite (face-to-face)
A37: メンバー国 | B37: 33 | C37: Yaman Muhammet Maruf | D37: Turkiye | E37: Head of Foreign Relations Department - AFAD | G37: Republic of Turkiye - Ministry of Interior - Disaster and Emergency Management Authority (AFAD) | H37: Onsite (face-to-face)
A38: メンバー国 | B38: 34 | C38: Ba Nam Nguyen | D38: Viet Nam | E38: Officer | F38: Department of Personnel and Organisation | G38: Ministry of Agriculture and Environment | H38: Onsite (face-to-face)
A39: メンバー国 | B39: 35 | C39: Truong Son Nguyen | D39: Viet Nam | E39: Deputy Director General | G39: Viet Nam Disaster and Dyke Management Authority | H39: Onsite (face-to-face)
A40: メンバー国 | B40: 36 | C40: Vu Thuy Duong | D40: Viet Nam | E40: Official | F40: Department of International Cooperation | G40: Viet Nam Disaster and Dyke Management Authority (VDDMA) | H40: Onsite (face-to-face)
A41: アドバイザー国 | B41: 1 | C41: Arthur David Gawn | D41: New Zealand | E41: Cheif Executive And Director General | G41: National Emergency Management Agency - New Zealand | H41: Onsite (face-to-face)
...
